<robot
  name="OSCAR">
  <link
    name="base_link">
    <inertial>
      <origin
        xyz="0 0 0"
        rpy="0 0 0" />
      <mass
        value="81.4616237556886" />
      <inertia
        ixx="9.92586702103313"
        ixy="0.284546866012666"
        ixz="2.0841773267857"
        iyy="7.22653314618283"
        iyz="-0.188391710489014"
        izz="10.6501056934012" />
    </inertial>
    <visual>
      <origin
        xyz="0 0 0"
        rpy="0 0 0" />
      <geometry>
        <!-- <mesh filename="package://oscar_description/meshes/base_link.STL" /> -->
        <box size="0.4 0.5 0.9"/>
      </geometry>
      <material
        name="">
        <color
          rgba="0.792156862745098 0.819607843137255 0.933333333333333 1" />
      </material>
    </visual>
    <collision>
      <origin
        xyz="0 0 0"
        rpy="0 0 0" />
      <geometry>
        <!-- <mesh filename="package://oscar_description/meshes/base_link.STL" /> -->
        <box size="0.4 0.5 0.9"/>
      </geometry>
    </collision>
  </link>

<link name="left-wheel">
  <visual>
      <origin rpy="-1.57075 0 0" xyz="0 0 0"/>
      <geometry>
        <cylinder length="0.5" radius="0.035"/>
      </geometry>
      <material name="">
        <color rgba="0.1 0.1 0.1 1" />
      </material>
  </visual>
  <collision>
      <origin rpy="-1.57075 0 0" xyz="0 0 0"/>
      <geometry>
        <cylinder length="0.5" radius="0.035"/>
      </geometry>
      <material name="">
        <color rgba="0.1 0.1 0.1 1" />
      </material>
  </collision>
  <inertial>
    <origin
      xyz="0.0 0.0 0.0"
      rpy="0 0 0" />
    <mass
      value="1" />
    <inertia
      ixx="0"
      ixy="0"
      ixz="0"
      iyy="0"
      iyz="0"
      izz="0" />
  </inertial>
</link>

<link name="right-wheel">
  <visual>
      <origin rpy="1.57075 0 0" xyz="0 0 0"/>
      <geometry>
        <cylinder length="0.5" radius="0.035"/>
      </geometry>
      <material name="">
        <color rgba="0.1 0.1 0.1 1" />
      </material>
  </visual>
  <collision>
      <origin rpy="1.57075 0 0" xyz="0 0 0"/>
      <geometry>
        <cylinder length="0.5" radius="0.035"/>
      </geometry>
      <material name="">
        <color rgba="0.1 0.1 0.1 1" />
      </material>
  </collision>
  <inertial>
    <origin
      xyz="0.0 0.0 0.0"
      rpy="0 0 0" />
    <mass
      value="1" />
    <inertia
      ixx="0"
      ixy="0"
      ixz="0"
      iyy="0"
      iyz="0"
      izz="0" />
  </inertial>
</link>

<joint name="left-wheel-joint" type="continuous">
   <parent link="base_link"/>
   <child link="left-wheel"/>
   <axis xyz="0 1 0"/>
   <origin xyz="0.2 0 -0.45"/>
</joint>

<joint name="right-wheel-joint" type="continuous">
  <parent link="base_link"/>
  <child link="right-wheel"/>
  <axis xyz="0 1 0"/>
  <origin xyz="-0.2 0 -0.45"/>
</joint>

</robot>
